// Try catch when native function exceptions are thrown

try {
    [1, 2, 3].slice("a");
} catch(err) {
    System.log(err.message);                                                                // expect Expected start index to be a number.
}

try {
    fun fn(a, b) {}
 
    fn();
} catch(err) {
    System.log(err.message);                                                                // expect Expected 2 arguments but got 0.
}

try {
    1 + true;
} catch(err) {
    System.log(err.message);                                                                // expect Invalid operands.
}

try {
    "dasda".startsWith(0);
} catch(err) {
    System.log(err.message);                                                                // expect Expected searchString to be a string.
}

try {
    -true;
} catch(err) {
    System.log(err.message);                                                                // expect Operand must be a number.
}

try {
    Number.toInteger(() -> {});
} catch(err) {
    System.log(err.message);                                                                // expect Expected argument to be a string or a number.
}

try {
    String.isString();
} catch(err) {
    System.log(err);                                                                        // expect instance of Error
    System.log(err.message);                                                                // expect Expected 1 arguments but got 0.
    System.log(err.stack);
    // expect [line 42] in script
}